Traceback (most recent call last):
  File "who-is-likely-to-have-approved-transactions.py", line 24, in <module>
    run(2)
  File "/home/cgzhu/anaconda3/envs/migration-plus/lib/python3.6/subprocess.py", line 423, in run
    with Popen(*popenargs, **kwargs) as process:
  File "/home/cgzhu/anaconda3/envs/migration-plus/lib/python3.6/subprocess.py", line 729, in __init__
    restore_signals, start_new_session)
  File "/home/cgzhu/anaconda3/envs/migration-plus/lib/python3.6/subprocess.py", line 1240, in _execute_child
    args = list(args)
TypeError: 'int' object is not iterable
