xAPI-Edu-Data.csv






Traceback (most recent call last):
  File "student-peroformance-analysis.py", line 243, in <module>
    ppn = Perceptron(n_iter=40, eta0=0.1, random_state=0)
  File "/home/cgzhu/anaconda3/envs/migration-plus/lib/python3.6/site-packages/sklearn/utils/validation.py", line 73, in inner_f
    return f(**kwargs)
TypeError: __init__() got an unexpected keyword argument 'n_iter'
[REPAIR EXEC TIME]: 6.260005474090576xAPI-Edu-Data.csv






Traceback (most recent call last):
  File "student-peroformance-analysis.py", line 243, in <module>
    ppn = Perceptron(n_iter=40, eta0=0.1, random_state=0)
  File "/home/cgzhu/anaconda3/envs/migration-plus/lib/python3.6/site-packages/sklearn/utils/validation.py", line 73, in inner_f
    return f(**kwargs)
TypeError: __init__() got an unexpected keyword argument 'n_iter'
[REPAIR EXEC TIME]: 5.0159595012664795xAPI-Edu-Data.csv






Traceback (most recent call last):
  File "student-peroformance-analysis.py", line 243, in <module>
    ppn = Perceptron(n_iter=40, eta0=0.1, random_state=0)
  File "/home/cgzhu/anaconda3/envs/migration-plus/lib/python3.6/site-packages/sklearn/utils/validation.py", line 73, in inner_f
    return f(**kwargs)
TypeError: __init__() got an unexpected keyword argument 'n_iter'
[REPAIR EXEC TIME]: 4.818039178848267